Traceback (most recent call last):
  File "/home/runner/Machine-Learning-Test-Project/venv/lib/python3.10/site-packages/wandb/sdk/wandb_config.py", line 163, in __getattr__
    return self.__getitem__(key)
  File "/home/runner/Machine-Learning-Test-Project/venv/lib/python3.10/site-packages/wandb/sdk/wandb_config.py", line 130, in __getitem__
    return self._items[key]
KeyError: 'activation_4'
The above exception was the direct cause of the following exception:
Traceback (most recent call last):
  File "/home/runner/Machine-Learning-Test-Project/test_model.py", line 111, in <module>
    main()
  File "/home/runner/Machine-Learning-Test-Project/test_model.py", line 62, in main
    model = create_model()
  File "/home/runner/Machine-Learning-Test-Project/test_model.py", line 43, in create_model
    Dense(10, activation=config.activation_4)
  File "/home/runner/Machine-Learning-Test-Project/venv/lib/python3.10/site-packages/wandb/sdk/wandb_config.py", line 165, in __getattr__
    raise AttributeError(
AttributeError: <class 'wandb.sdk.wandb_config.Config'> object has no attribute 'activation_4'